<?xml version="1.0" ?>
<!-- =================================================================================== -->
<!-- |    This document was autogenerated by xacro from ugv.xacro                      | -->
<!-- |    EDITING THIS FILE BY HAND IS NOT RECOMMENDED                                 | -->
<!-- =================================================================================== -->
<robot name="ugv">
  <link name="wheelBL">
    <inertial>
      <mass value="1.0"/>
      <origin xyz="0 0 0"/>
      <inertia ixx="0.01" ixy="0" ixz="0" iyy="0.01" iyz="0" izz="0.01"/>
    </inertial>
    <visual>
      <origin rpy="1.57 0.0 0.0" xyz="0.0 0.0 0.0"/>
      <geometry>
        <mesh filename="package://ugv/mesh/tyre.obj" scale="1 1 1"/>
      </geometry>
      <material name="black"/>
    </visual>
  </link>
  <link name="wheelFL">
    <inertial>
      <mass value="1.0"/>
      <origin xyz="0 0 0"/>
      <inertia ixx="0.01" ixy="0" ixz="0" iyy="0.01" iyz="0" izz="0.01"/>
    </inertial>
    <visual>
      <origin rpy="1.57 0.0 0.0" xyz="0.0 0.0 0.0"/>
      <geometry>
        <mesh filename="package://ugv/mesh/tyre.obj" scale="1 1 1"/>
      </geometry>
      <material name="black"/>
    </visual>
  </link>
  <link name="wheelFR">
    <inertial>
      <mass value="1.0"/>
      <origin xyz="0 0 0"/>
      <inertia ixx="0.01" ixy="0" ixz="0" iyy="0.01" iyz="0" izz="0.01"/>
    </inertial>
    <visual>
      <origin rpy="1.57 0.0 0.0" xyz="0.0 0.0 0.0"/>
      <geometry>
        <mesh filename="package://ugv/mesh/tyre.obj" scale="1 1 1"/>
      </geometry>
      <material name="black"/>
    </visual>
  </link>
  <link name="wheelBR">
    <inertial>
      <mass value="1.0"/>
      <origin xyz="0 0 0"/>
      <inertia ixx="0.01" ixy="0" ixz="0" iyy="0.01" iyz="0" izz="0.01"/>
    </inertial>
    <visual>
      <origin rpy="1.57 0.0 0.0" xyz="0.0 0.0 0.0"/>
      <geometry>
        <mesh filename="package://ugv/mesh/tyre.obj" scale="1 1 1"/>
      </geometry>
      <material name="black"/>
    </visual>
  </link>
  <material name="black">
    <color rgba="1 1 1 1.0"/>
  </material>
  <material name="grey">
    <color rgba="1 0.0 0.0 1.0"/>
  </material>
  <link name="base_link">
    <inertial>
      <mass value="1.0"/>
      <origin xyz="0 0 0"/>
      <inertia ixx="0.01" ixy="0" ixz="0" iyy="0.01" iyz="0" izz="0.01"/>
    </inertial>
    <visual>
      <origin rpy="1.57 0.0 0.0" xyz="0.0 0.0 0.009"/>
      <geometry>
        <mesh filename="package://ugv/mesh/mainBody.obj" scale="1 1 1"/>
      </geometry>
      <material name="grey"/>
    </visual>
  </link>
  <link name="lidar">
    <inertial>
      <mass value="1.0"/>
      <origin xyz="0 0 0"/>
      <inertia ixx="0.01" ixy="0" ixz="0" iyy="0.01" iyz="0" izz="0.01"/>
    </inertial>
    <visual>
      <origin rpy="1.57 0.0 0.0" xyz="0.0 0.0 0.009"/>
      <geometry>
        <mesh filename="package://ugv/mesh/lidar.obj" scale="1 1 1"/>
      </geometry>
      <material name="grey"/>
    </visual>
  </link>
  <link name="shaftF">
    <inertial>
      <mass value="1.0"/>
      <origin xyz="0 0 0"/>
      <inertia ixx="0.01" ixy="0" ixz="0" iyy="0.01" iyz="0" izz="0.01"/>
    </inertial>
    <visual>
      <origin rpy="1.57 0.0 0.0" xyz="0.0 0.0 0.009"/>
      <geometry>
        <mesh filename="package://ugv/mesh/shaft.obj" scale="1 1 1"/>
      </geometry>
      <material name="grey"/>
    </visual>
  </link>
  <link name="shaftB">
    <inertial>
      <mass value="1.0"/>
      <origin xyz="0 0 0"/>
      <inertia ixx="0.01" ixy="0" ixz="0" iyy="0.01" iyz="0" izz="0.01"/>
    </inertial>
    <visual>
      <origin rpy="1.57 0.0 0.0" xyz="0.0 0.0 0.009"/>
      <geometry>
        <mesh filename="package://ugv/mesh/shaft.obj" scale="1 1 1"/>
      </geometry>
      <material name="grey"/>
    </visual>
  </link>
  <joint name="mainBody_shaftF" type="fixed">
    <parent link="base_link"/>
    <child link="shaftF"/>
    <origin rpy="0.0 0.0 0.0" xyz="0.07 0 0.0105"/>
  </joint>
  <joint name="mainBody_shaftB" type="fixed">
    <parent link="base_link"/>
    <child link="shaftB"/>
    <origin rpy="0.0 0.0 0.0" xyz="-0.07 0 0.0105"/>
  </joint>
  <joint name="mainBody_WheelBL" type="continuous">
    <parent link="base_link"/>
    <child link="wheelBL"/>
    <origin rpy="0.0 0.0 0.0" xyz="-0.07 0.0525 0.019"/>
    <axis xyz="0 1 0"/>
    <limit effort="0" lower="0" upper="0" velocity="0"/>
  </joint>
  <joint name="mainBody_WheelFL" type="continuous">
    <parent link="base_link"/>
    <child link="wheelFL"/>
    <origin rpy="0.0 0.0 0.0" xyz="0.07 0.0525 0.019"/>
    <axis xyz="0 1 0"/>
    <limit effort="0" lower="0" upper="0" velocity="0"/>
  </joint>
  <joint name="mainBody_WheelFR" type="continuous">
    <parent link="base_link"/>
    <child link="wheelFR"/>
    <origin rpy="0.0 0.0 0.0" xyz="0.07 -0.0525 0.019"/>
    <axis xyz="0 1 0"/>
    <limit effort="0" lower="0" upper="0" velocity="0"/>
  </joint>
  <joint name="mainBody_WheelBR" type="continuous">
    <parent link="base_link"/>
    <child link="wheelBR"/>
    <origin rpy="0.0 0.0 0.0" xyz="-0.07 -0.0525 0.019"/>
    <axis xyz="0 1 0"/>
    <limit effort="0" lower="0" upper="0" velocity="0"/>
  </joint>
  <joint name="mainBody_Lidar" type="fixed">
    <parent link="base_link"/>
    <child link="lidar"/>
    <origin rpy="0.0 0.0 0.0" xyz="0.075 0 0.04"/>
  </joint>
</robot>
