<?xml version="1.0" ?>
<!-- =================================================================================== -->
<!-- |    This document was autogenerated by xacro from /home/david/ros2_ws/src/ugv/urdf/ugvGazebo.xacro | -->
<!-- |    EDITING THIS FILE BY HAND IS NOT RECOMMENDED                                 | -->
<!-- =================================================================================== -->
<robot name="ugv">
  <link name="wheelBL">
    <visual>
      <origin rpy="1.57 0.0 0.0" xyz="0.0 0.0 0.009"/>
      <geometry>
        <mesh filename="package://ugv/mesh/tyre.obj" scale="1 1 1"/>
      </geometry>
      <material name="black"/>
    </visual>
    <inertial>
      <mass value="0.2"/>
      <inertia ixx="0.00695" ixy="0.0" ixz="0.0" iyy="0.00695" iyz="0.0" izz="0.01203"/>
    </inertial>
    <gazebo>
      <mu>1.0</mu>
      <mu2>0.8</mu2>
      <material>Gazebo/Black</material>
    </gazebo>
  </link>
  <link name="wheelFL">
    <visual>
      <origin rpy="1.57 0.0 0.0" xyz="0.0 0.0 0.009"/>
      <geometry>
        <mesh filename="package://ugv/mesh/tyre.obj" scale="1 1 1"/>
      </geometry>
      <material name="black"/>
    </visual>
    <inertial>
      <mass value="0.2"/>
      <inertia ixx="0.00695" ixy="0.0" ixz="0.0" iyy="0.00695" iyz="0.0" izz="0.01203"/>
    </inertial>
    <gazebo>
      <mu>1.0</mu>
      <mu2>0.8</mu2>
      <material>Gazebo/Black</material>
    </gazebo>
  </link>
  <link name="wheelFR">
    <visual>
      <origin rpy="1.57 0.0 0.0" xyz="0.0 0.0 0.009"/>
      <geometry>
        <mesh filename="package://ugv/mesh/tyre.obj" scale="1 1 1"/>
      </geometry>
      <material name="black"/>
    </visual>
    <inertial>
      <mass value="0.2"/>
      <inertia ixx="0.00695" ixy="0.0" ixz="0.0" iyy="0.00695" iyz="0.0" izz="0.01203"/>
    </inertial>
    <gazebo>
      <mu>1.0</mu>
      <mu2>0.8</mu2>
      <material>Gazebo/Black</material>
    </gazebo>
  </link>
  <link name="wheelBR">
    <visual>
      <origin rpy="1.57 0.0 0.0" xyz="0.0 0.0 0.009"/>
      <geometry>
        <mesh filename="package://ugv/mesh/tyre.obj" scale="1 1 1"/>
      </geometry>
      <material name="black"/>
    </visual>
    <inertial>
      <mass value="0.2"/>
      <inertia ixx="0.00695" ixy="0.0" ixz="0.0" iyy="0.00695" iyz="0.0" izz="0.01203"/>
    </inertial>
    <gazebo>
      <mu>1.0</mu>
      <mu2>0.8</mu2>
      <material>Gazebo/Black</material>
    </gazebo>
  </link>
  <material name="black">
    <color rgba="1 1 1 1.0"/>
  </material>
  <material name="grey">
    <color rgba="1 0.0 0.0 1.0"/>
  </material>
  <link name="base_link">
    <visual>
      <origin rpy="1.57 0.0 0.0" xyz="0.0 0.0 0.009"/>
      <geometry>
        <mesh filename="package://ugv/mesh/mainBody.obj" scale="1 1 1"/>
      </geometry>
      <material name="grey"/>
    </visual>
    <inertial>
      <mass value="0.2"/>
      <inertia ixx="0.067" ixy="0.0" ixz="0.0" iyy="0.227" iyz="0.0" izz="0.173"/>
    </inertial>
    <gazebo>
      <mu>1.0</mu>
      <mu2>0.8</mu2>
      <material>Gazebo/Black</material>
    </gazebo>
  </link>
  <link name="lidar">
    <visual>
      <origin rpy="1.57 0.0 0.0" xyz="0.0 0.0 0.009"/>
      <geometry>
        <mesh filename="package://ugv/mesh/lidar.obj" scale="1 1 1"/>
      </geometry>
      <material name="grey"/>
    </visual>
  </link>
  <link name="shaftF">
    <visual>
      <origin rpy="1.57 0.0 0.0" xyz="0.0 0.0 0.009"/>
      <geometry>
        <mesh filename="package://ugv/mesh/shaft.obj" scale="1 1 1"/>
      </geometry>
      <material name="grey"/>
    </visual>
  </link>
  <link name="shaftB">
    <visual>
      <origin rpy="1.57 0.0 0.0" xyz="0.0 0.0 0.009"/>
      <geometry>
        <mesh filename="package://ugv/mesh/shaft.obj" scale="1 1 1"/>
      </geometry>
      <material name="grey"/>
    </visual>
  </link>
  <joint name="mainBody_shaftF" type="fixed">
    <parent link="base_link"/>
    <child link="shaftF"/>
    <origin rpy="0.0 0.0 0.0" xyz="0.07 0 0.0105"/>
  </joint>
  <joint name="mainBody_shaftB" type="fixed">
    <parent link="base_link"/>
    <child link="shaftB"/>
    <origin rpy="0.0 0.0 0.0" xyz="-0.07 0 0.0105"/>
  </joint>
  <joint name="mainBody_WheelBL" type="continuous">
    <parent link="base_link"/>
    <child link="wheelBL"/>
    <origin rpy="0.0 0.0 0.0" xyz="-0.07 0.0525 0.01"/>
    <axis xyz="0 1 0"/>
    <limit effort="0" lower="0" upper="0" velocity="0"/>
  </joint>
  <joint name="mainBody_WheelFL" type="continuous">
    <parent link="base_link"/>
    <child link="wheelFL"/>
    <origin rpy="0.0 0.0 0.0" xyz="0.07 0.0525 0.010"/>
    <axis xyz="0 1 0"/>
    <limit effort="0" lower="0" upper="0" velocity="0"/>
  </joint>
  <joint name="mainBody_WheelFR" type="continuous">
    <parent link="base_link"/>
    <child link="wheelFR"/>
    <origin rpy="0.0 0.0 0.0" xyz="0.07 -0.0525 0.010"/>
    <axis xyz="0 1 0"/>
    <limit effort="0" lower="0" upper="0" velocity="0"/>
  </joint>
  <joint name="mainBody_WheelBR" type="continuous">
    <parent link="base_link"/>
    <child link="wheelBR"/>
    <origin rpy="0.0 0.0 0.0" xyz="-0.07 -0.0525 0.010"/>
    <axis xyz="0 1 0"/>
    <limit effort="0" lower="0" upper="0" velocity="0"/>
  </joint>
  <joint name="mainBody_Lidar" type="fixed">
    <parent link="base_link"/>
    <child link="lidar"/>
    <origin rpy="0.0 0.0 0.0" xyz="0.075 0 0.04"/>
  </joint>
</robot>
